<mujoco model="example">
    <worldbody>
        <light diffuse=".5 .5 .5" pos="0 0 3" dir="0 0 -1"/>
        <body name="body1" pos="0 0 0">
            <inertial mass="0.1" diaginertia="0.0001 0.0001 0.0001" pos="0 0 0"/>
            <joint name="joint1" type="hinge" axis="0 1 0" pos="0 0 0"/>
            <geom type="box" size=".1 .2 .3" rgba="0 .9 0 1"/>
            <!-- Geom and other body definitions -->
        </body>
    </worldbody>
    <actuator>
        <position joint="joint1" kp="10000"/>
    </actuator>
</mujoco>
