<mujoco model="stepMARKIV">

     <!-- <compiler angle="radian"/> -->
  <asset>
    <mesh name="JETSON" file="../scad/JETSON.stl" scale="0.001 0.001 0.001"/>
    <mesh name="BATT" file="../scad/BATT.stl" scale="0.001 0.001 0.001"/>
    <!-- <mesh name="LEFTLEG" file="../scad/LEFTLEG.stl" scale="0.001 0.001 0.001"/> -->
    <mesh name="PELVIS" file="../scad/PELVIS.stl" scale="0.001 0.001 0.001"/>
    <mesh name="HIP" file="../scad/HIP.stl" scale="0.001 0.001 0.001"/>
    <mesh name="THIGH" file="../scad/THIGH.stl" scale="0.001 0.001 0.001"/>
    <mesh name="SHIN" file="../scad/SHIN.stl" scale="0.001 0.001 0.001"/>
    <mesh name="SHINLINK" file="../scad/SHINLINK.stl" scale="0.001 0.001 0.001"/>
    <mesh name="FOOT" file="../scad/FOOT.stl" scale="0.001 0.001 0.001"/>
  </asset>



   <default>
      <joint axis="1 0 0" limited="true" range="-10 10" damping="0.1"/>
      <geom size="1 1 .01" type="box"/>

   </default>

   <worldbody>
      <body>
         <joint name="free_joint" pos="0 0 0" type="free"/>
         <geom pos="0 0 0" quat="1 0 0 0" type="mesh" rgba="0 1 1 0.5" mesh="BATT"/>
         <geom pos="0 0 .02" quat="1 0 0 0" type="mesh" rgba="0 1 0.3 1" mesh="JETSON"/>
         <geom pos="0 0 .01" quat="1 0 0 0" type="mesh" rgba=".1 .3 .1 1" mesh="PELVIS"/>
         <geom pos="-0.08 0 .01" quat="0 0 0 1" type="mesh" rgba=".1 .3 .1 1" mesh="PELVIS"/>

         <body>
            <joint pos="-0.05 .058 0.01" name="servo_4" axis="1 0 0" limited="true" damping="0.1"/>
            <geom pos="0 0 0" quat="1 0 0 0" type="mesh" rgba="1 1 1 1" mesh="HIP"/>
            <body pos=".00 0 0">
               <joint pos="0 .05 -0.01" name="servo_3" axis="0 1 0" limited="true" damping="0.1"/>
               <geom pos="0 -0 0" quat="1 0 0 0" type="mesh" rgba="1 1 1 1" mesh="THIGH"/>
               <body pos=".00 0 0">
                  <joint  pos="-0.001 0.05 -0.168" name="servo_2" axis="0 1 0" limited="true" damping="0.1"/>
                  <geom pos="0 -0 0" quat="1 0 0 0" type="mesh" rgba="1 1 1 1" mesh="SHIN"/>
                  <body pos=".00 0 0">
                     <joint  pos="0 0.05 -0.298" name="servo_1" axis="0 1 0" limited="true" damping="0.1"/>
                     <geom pos="0 -0 0" quat="1 0 0 0" type="mesh" rgba="1 1 1 1" mesh="FOOT"/>
                  </body>
               </body>
            </body>
         </body>

         <body>
            <joint pos="-0.05 -.058 0.01" name="servo_5" axis="1 0 0" limited="true" damping="0.1"/>
            <geom pos="0 -0.11 0" quat="1 0 0 0" type="mesh" rgba="1 1 1 1" mesh="HIP"/>
            <body pos=".00 0 0">
               <joint pos="0 -.058 -0.01" name="servo_6" axis="0 1 0" limited="true" damping="0.1"/>
               <geom pos="0 -0.11 0" quat="1 0 0 0" type="mesh" rgba="1 1 1 1" mesh="THIGH"/>
               <body pos=".00 0 0">
                  <joint  pos="-0.001 -0.058 -0.168" name="servo_7" axis="0 1 0" limited="true" damping="0.1"/>
                  <geom pos="0 -0.11 0" quat="1 0 0 0" type="mesh" rgba="1 1 1 1" mesh="SHIN"/>
                  <body pos=".00 0 0">
                     <joint  pos="0 -0.058 -0.298" name="servo_8" axis="0 1 0" limited="true" damping="0.1"/>
                     <geom pos="0 -0.11 0" quat="1 0 0 0" type="mesh" rgba="1 1 1 1" mesh="FOOT"/>
                  </body>
               </body>
            </body>
         </body>
      </body>


      <body mocap="true">
         <geom  pos="0 0.0 -0.325"/>
      </body>
   </worldbody>

 
  <actuator>
    <position ctrllimited="true" ctrlrange="-10 10" gear="1" joint="servo_1"/>
  </actuator>
  <actuator>
    <position ctrllimited="true" ctrlrange="-10 10" gear="1" joint="servo_2"/>
  </actuator>
  <actuator>
    <position ctrllimited="true" ctrlrange="-10 10" gear="1" joint="servo_3"/>
  </actuator>
  <actuator>
    <position ctrllimited="true" ctrlrange="-10 10" gear="1" joint="servo_4"/>
  </actuator>
  <actuator>
    <position ctrllimited="true" ctrlrange="-10 10" gear="1" joint="servo_5"/>
  </actuator>
  <actuator>
    <position ctrllimited="true" ctrlrange="-10 10" gear="1" joint="servo_6"/>
  </actuator>
  <actuator>
    <position ctrllimited="true" ctrlrange="-10 10" gear="1" joint="servo_7"/>
  </actuator>
  <actuator>
    <position ctrllimited="true" ctrlrange="-10 10" gear="1" joint="servo_8"/>
  </actuator>
</mujoco>